"""Tests for storage recovery handlers"""

import json
import pytest
from datetime import datetime, timedelta
from unittest.mock import AsyncMock, MagicMock, Mock, PropertyMock
from bot_v2.state.recovery.handlers.storage import StorageRecoveryHandlers
from bot_v2.state.recovery.models import (
    FailureEvent,
    FailureType,
    RecoveryMode,
    RecoveryOperation,
    RecoveryStatus,
)


@pytest.fixture
def mock_state_manager():
    """Mock state manager"""
    manager = Mock()
    manager.redis_client = Mock()
    manager.pg_conn = MagicMock()
    manager.s3_client = Mock()
    manager.set_state = AsyncMock()
    manager.get_state = AsyncMock()
    return manager


@pytest.fixture
def mock_checkpoint_handler():
    """Mock checkpoint handler"""
    handler = Mock()
    handler.get_latest_checkpoint = Mock()
    handler.find_valid_checkpoint = AsyncMock()
    handler.restore_from_checkpoint = AsyncMock()
    return handler


@pytest.fixture
def mock_backup_manager():
    """Mock backup manager"""
    manager = Mock()
    manager.restore_latest_backup = AsyncMock()
    return manager


@pytest.fixture
def storage_handlers(mock_state_manager, mock_checkpoint_handler, mock_backup_manager):
    """Create StorageRecoveryHandlers instance"""
    return StorageRecoveryHandlers(
        mock_state_manager,
        mock_checkpoint_handler,
        mock_backup_manager,
    )


@pytest.fixture
def recovery_operation():
    """Create sample recovery operation"""
    failure_event = FailureEvent(
        failure_type=FailureType.REDIS_DOWN,
        timestamp=datetime.utcnow(),
        severity="high",
        affected_components=["cache"],
        error_message="Redis connection lost",
    )

    return RecoveryOperation(
        operation_id="REC_TEST_001",
        failure_event=failure_event,
        recovery_mode=RecoveryMode.AUTOMATIC,
        status=RecoveryStatus.IN_PROGRESS,
        started_at=datetime.utcnow(),
    )


class TestStorageRecoveryHandlers:
    """Test suite for StorageRecoveryHandlers"""

    @pytest.mark.asyncio
    async def test_recover_redis_success(self, storage_handlers, recovery_operation):
        """Test successful Redis recovery"""
        # Mock PostgreSQL data
        mock_cursor = Mock()
        mock_cursor.fetchall.return_value = [
            {"key": "test_key_1", "data": {"value": 123}},
            {"key": "test_key_2", "data": {"value": 456}},
        ]

        storage_handlers.state_manager.pg_conn.cursor.return_value.__enter__.return_value = (
            mock_cursor
        )

        success = await storage_handlers.recover_redis(recovery_operation)

        assert success is True
        assert len(recovery_operation.actions_taken) == 2
        assert "Starting Redis recovery" in recovery_operation.actions_taken[0]
        assert "Recovered 2 keys" in recovery_operation.actions_taken[1]

    @pytest.mark.asyncio
    async def test_recover_redis_no_pg_connection(self, storage_handlers, recovery_operation):
        """Test Redis recovery without PostgreSQL connection"""
        storage_handlers.state_manager.pg_conn = None

        success = await storage_handlers.recover_redis(recovery_operation)

        assert success is False

    @pytest.mark.asyncio
    async def test_recover_redis_pg_query_fails(self, storage_handlers, recovery_operation):
        """Test Redis recovery when PostgreSQL query fails"""
        storage_handlers.state_manager.pg_conn.cursor.side_effect = Exception(
            "Query failed"
        )

        success = await storage_handlers.recover_redis(recovery_operation)

        assert success is False
        assert any("error" in action.lower() for action in recovery_operation.actions_taken)

    @pytest.mark.asyncio
    async def test_recover_redis_partial_restore(self, storage_handlers, recovery_operation):
        """Test Redis recovery with partial key restoration"""
        mock_cursor = Mock()
        mock_cursor.fetchall.return_value = [
            {"key": "test_key_1", "data": {"value": 123}},
            {"key": "test_key_2", "data": {"value": 456}},
        ]

        storage_handlers.state_manager.pg_conn.cursor.return_value.__enter__.return_value = (
            mock_cursor
        )

        # Make Redis set fail for one key
        storage_handlers.state_manager.redis_client.set = Mock(
            side_effect=[None, Exception("Redis error")]
        )

        success = await storage_handlers.recover_redis(recovery_operation)

        # Should still succeed if at least one key was restored
        assert success is True

    @pytest.mark.asyncio
    async def test_recover_postgres_from_checkpoint(
        self, storage_handlers, recovery_operation
    ):
        """Test PostgreSQL recovery from checkpoint"""
        mock_checkpoint = Mock()
        mock_checkpoint.checkpoint_id = "CKPT_001"
        mock_checkpoint.timestamp = datetime.utcnow() - timedelta(seconds=30)

        storage_handlers.checkpoint_handler.get_latest_checkpoint.return_value = (
            mock_checkpoint
        )
        storage_handlers.checkpoint_handler.restore_from_checkpoint.return_value = True

        success = await storage_handlers.recover_postgres(recovery_operation)

        assert success is True
        assert "Restored from checkpoint CKPT_001" in recovery_operation.actions_taken[1]
        assert recovery_operation.data_loss_estimate is not None
        assert "seconds" in recovery_operation.data_loss_estimate

    @pytest.mark.asyncio
    async def test_recover_postgres_no_checkpoint_use_backup(
        self, storage_handlers, recovery_operation
    ):
        """Test PostgreSQL recovery from backup when no checkpoint"""
        storage_handlers.checkpoint_handler.get_latest_checkpoint.return_value = None
        storage_handlers.backup_manager.restore_latest_backup.return_value = True

        success = await storage_handlers.recover_postgres(recovery_operation)

        assert success is True
        storage_handlers.backup_manager.restore_latest_backup.assert_called_once()

    @pytest.mark.asyncio
    async def test_recover_postgres_no_checkpoint_no_backup(
        self, storage_handlers, recovery_operation
    ):
        """Test PostgreSQL recovery with no checkpoint and no backup manager"""
        storage_handlers.checkpoint_handler.get_latest_checkpoint.return_value = None
        storage_handlers.backup_manager = None

        success = await storage_handlers.recover_postgres(recovery_operation)

        assert success is False

    @pytest.mark.asyncio
    async def test_recover_postgres_checkpoint_restore_fails(
        self, storage_handlers, recovery_operation
    ):
        """Test PostgreSQL recovery when checkpoint restore fails"""
        mock_checkpoint = Mock()
        mock_checkpoint.checkpoint_id = "CKPT_001"
        mock_checkpoint.timestamp = datetime.utcnow()

        storage_handlers.checkpoint_handler.get_latest_checkpoint.return_value = (
            mock_checkpoint
        )
        storage_handlers.checkpoint_handler.restore_from_checkpoint.return_value = False

        success = await storage_handlers.recover_postgres(recovery_operation)

        assert success is False

    @pytest.mark.asyncio
    async def test_recover_s3_success(self, storage_handlers, recovery_operation):
        """Test S3 recovery (fallback mode)"""
        success = await storage_handlers.recover_s3(recovery_operation)

        assert success is True
        storage_handlers.state_manager.set_state.assert_called_once_with(
            "system:s3_available", False
        )
        assert "fallback" in recovery_operation.actions_taken[1].lower()

    @pytest.mark.asyncio
    async def test_recover_s3_set_state_fails(self, storage_handlers, recovery_operation):
        """Test S3 recovery when set_state fails"""
        storage_handlers.state_manager.set_state.side_effect = Exception("State error")

        success = await storage_handlers.recover_s3(recovery_operation)

        assert success is False

    @pytest.mark.asyncio
    async def test_recover_from_corruption_success(
        self, storage_handlers, recovery_operation
    ):
        """Test successful data corruption recovery"""
        mock_checkpoint = Mock()
        mock_checkpoint.checkpoint_id = "CKPT_VALID"
        mock_checkpoint.timestamp = datetime.utcnow() - timedelta(minutes=5)

        storage_handlers.checkpoint_handler.find_valid_checkpoint.return_value = (
            mock_checkpoint
        )
        storage_handlers.checkpoint_handler.restore_from_checkpoint.return_value = True

        # Mock transaction replay
        storage_handlers._replay_transactions_from = AsyncMock(return_value=True)

        success = await storage_handlers.recover_from_corruption(recovery_operation)

        assert success is True
        assert "valid checkpoint" in recovery_operation.actions_taken[1].lower()
        assert "Replayed transactions" in recovery_operation.actions_taken[2]

    @pytest.mark.asyncio
    async def test_recover_from_corruption_no_valid_checkpoint(
        self, storage_handlers, recovery_operation
    ):
        """Test corruption recovery with no valid checkpoint"""
        storage_handlers.checkpoint_handler.find_valid_checkpoint.return_value = None

        success = await storage_handlers.recover_from_corruption(recovery_operation)

        assert success is False

    @pytest.mark.asyncio
    async def test_recover_from_corruption_restore_fails(
        self, storage_handlers, recovery_operation
    ):
        """Test corruption recovery when checkpoint restore fails"""
        mock_checkpoint = Mock()
        storage_handlers.checkpoint_handler.find_valid_checkpoint.return_value = (
            mock_checkpoint
        )
        storage_handlers.checkpoint_handler.restore_from_checkpoint.return_value = False

        success = await storage_handlers.recover_from_corruption(recovery_operation)

        assert success is False

    @pytest.mark.asyncio
    async def test_recover_from_corruption_with_exception(
        self, storage_handlers, recovery_operation
    ):
        """Test corruption recovery with exception"""
        storage_handlers.checkpoint_handler.find_valid_checkpoint.side_effect = Exception(
            "Checkpoint error"
        )

        success = await storage_handlers.recover_from_corruption(recovery_operation)

        assert success is False
        assert any("error" in action.lower() for action in recovery_operation.actions_taken)

    @pytest.mark.asyncio
    async def test_replay_transactions_from_success(self, storage_handlers):
        """Test transaction replay success"""
        timestamp = datetime.utcnow() - timedelta(minutes=5)

        result = await storage_handlers._replay_transactions_from(timestamp)

        # Currently returns True as placeholder
        assert result is True

    @pytest.mark.asyncio
    async def test_replay_transactions_from_failure(self, storage_handlers):
        """Test transaction replay failure"""
        # Test that method handles errors gracefully
        with pytest.raises(Exception):
            # This would test actual implementation when available
            raise Exception("Transaction log not found")
